{
  "verification_type": "TDD-based ACC Verification",
  "target": "VM-4 (edge1)",
  "timestamp": "2025-09-13T19:00:47+00:00",
  "total_duration_seconds": 9.09,
  "phases": [
    {
      "phase": "ACC-12",
      "status": "FAIL",
      "duration_seconds": 0.87,
      "test_output": "============================= test session starts ==============================\nplatform linux -- Python 3.11.9, pytest-8.4.2, pluggy-1.6.0 -- /home/ubuntu/.pyenv/versions/3.11.9/bin/python3\ncachedir: .pytest_cache\nmetadata: {'Python': '3.11.9', 'Platform': 'Linux-5.15.0-100-generic-x86_64-with-glibc2.35', 'Packages': {'pytest': '8.4.2', 'pluggy': '1.6.0'}, 'Plugins': {'json-report': '1.5.0', 'metadata': '3.1.1', 'timeout': '2.4.0'}}\nrootdir: /home/ubuntu\nplugins: json-report-1.5.0, metadata-3.1.1, timeout-2.4.0\ncollecting ... collected 8 items\n\ntests/test_acc12_rootsync.py::TestACC12RootSyncVerification::test_artifacts_directory_exists PASSED [ 12%]\ntests/test_acc12_rootsync.py::TestACC12RootSyncVerification::test_config_management_namespace_exists FAILED [ 25%]\ntests/test_acc12_rootsync.py::TestACC12RootSyncVerification::test_generate_acc12_artifacts FAILED [ 37%]\ntests/test_acc12_rootsync.py::TestACC12RootSyncVerification::test_kubectl_context_exists FAILED [ 50%]\ntests/test_acc12_rootsync.py::TestACC12RootSyncVerification::test_rootsync_is_synced FAILED [ 62%]\ntests/test_acc12_rootsync.py::TestACC12RootSyncVerification::test_rootsync_points_to_gitops_edge2_config FAILED [ 75%]\ntests/test_acc12_rootsync.py::TestACC12RootSyncVerification::test_rootsync_resource_exists FAILED [ 87%]\ntests/test_acc12_rootsync.py::TestACC12Implementation::test_full_acc12_workflow PASSED [100%]\n\n=================================== FAILURES ===================================\n____ TestACC12RootSyncVerification.test_config_management_namespace_exists _____\ntests/test_acc12_rootsync.py:48: in test_config_management_namespace_exists\n    self.assertEqual(result.returncode, 0,\nE   AssertionError: 1 != 0 : Namespace config-management-system should exist in edge2\n_________ TestACC12RootSyncVerification.test_generate_acc12_artifacts __________\ntests/test_acc12_rootsync.py:122: in test_generate_acc12_artifacts\n    self.assertEqual(result.returncode, 0, \"Should be able to get RootSync data\")\nE   AssertionError: 1 != 0 : Should be able to get RootSync data\n__________ TestACC12RootSyncVerification.test_kubectl_context_exists ___________\ntests/test_acc12_rootsync.py:40: in test_kubectl_context_exists\n    self.assertIn(\"edge2\", result.stdout, \"edge2 context should exist in kubectl config\")\nE   AssertionError: 'edge2' not found in 'kind-edge\\n' : edge2 context should exist in kubectl config\n____________ TestACC12RootSyncVerification.test_rootsync_is_synced _____________\ntests/test_acc12_rootsync.py:71: in test_rootsync_is_synced\n    self.assertEqual(result.returncode, 0, \"Should be able to get RootSync status\")\nE   AssertionError: 1 != 0 : Should be able to get RootSync status\n__ TestACC12RootSyncVerification.test_rootsync_points_to_gitops_edge2_config ___\ntests/test_acc12_rootsync.py:94: in test_rootsync_points_to_gitops_edge2_config\n    self.assertEqual(result.returncode, 0, \"Should be able to get RootSync configuration\")\nE   AssertionError: 1 != 0 : Should be able to get RootSync configuration\n_________ TestACC12RootSyncVerification.test_rootsync_resource_exists __________\ntests/test_acc12_rootsync.py:58: in test_rootsync_resource_exists\n    self.assertEqual(result.returncode, 0, \"RootSync resource should exist\")\nE   AssertionError: 1 != 0 : RootSync resource should exist\n--------------------------------- JSON report ----------------------------------\nreport saved to: artifacts/edge1/acc-12_test_results.json\n=========================== short test summary info ============================\nFAILED tests/test_acc12_rootsync.py::TestACC12RootSyncVerification::test_config_management_namespace_exists\nFAILED tests/test_acc12_rootsync.py::TestACC12RootSyncVerification::test_generate_acc12_artifacts\nFAILED tests/test_acc12_rootsync.py::TestACC12RootSyncVerification::test_kubectl_context_exists\nFAILED tests/test_acc12_rootsync.py::TestACC12RootSyncVerification::test_rootsync_is_synced\nFAILED tests/test_acc12_rootsync.py::TestACC12RootSyncVerification::test_rootsync_points_to_gitops_edge2_config\nFAILED tests/test_acc12_rootsync.py::TestACC12RootSyncVerification::test_rootsync_resource_exists\n========================= 6 failed, 2 passed in 0.53s ==========================\n",
      "test_errors": "",
      "return_code": 1
    },
    {
      "phase": "ACC-13",
      "status": "FAIL",
      "duration_seconds": 4.69,
      "test_output": "============================= test session starts ==============================\nplatform linux -- Python 3.11.9, pytest-8.4.2, pluggy-1.6.0 -- /home/ubuntu/.pyenv/versions/3.11.9/bin/python3\ncachedir: .pytest_cache\nmetadata: {'Python': '3.11.9', 'Platform': 'Linux-5.15.0-100-generic-x86_64-with-glibc2.35', 'Packages': {'pytest': '8.4.2', 'pluggy': '1.6.0'}, 'Plugins': {'json-report': '1.5.0', 'metadata': '3.1.1', 'timeout': '2.4.0'}}\nrootdir: /home/ubuntu\nplugins: json-report-1.5.0, metadata-3.1.1, timeout-2.4.0\ncollecting ... collected 8 items\n\ntests/test_acc13_slo.py::TestACC13SLOEndpoints::test_baseline_response_time_measurement FAILED [ 12%]\ntests/test_acc13_slo.py::TestACC13SLOEndpoints::test_discover_slo_services FAILED [ 25%]\ntests/test_acc13_slo.py::TestACC13SLOEndpoints::test_generate_acc13_artifacts PASSED [ 37%]\ntests/test_acc13_slo.py::TestACC13SLOEndpoints::test_load_test_moves_p95 FAILED [ 50%]\ntests/test_acc13_slo.py::TestACC13SLOEndpoints::test_slo_endpoint_responds_to_health_check PASSED [ 62%]\ntests/test_acc13_slo.py::TestACC13SLOEndpoints::test_slo_endpoints_are_reachable FAILED [ 75%]\ntests/test_acc13_slo.py::TestACC13Performance::test_concurrent_load_handling FAILED [ 87%]\ntests/test_acc13_slo.py::TestACC13Performance::test_slo_endpoints_meet_performance_requirements PASSED [100%]\n\n=================================== FAILURES ===================================\n________ TestACC13SLOEndpoints.test_baseline_response_time_measurement _________\ntests/test_acc13_slo.py:153: in test_baseline_response_time_measurement\n    self.assertGreater(len(baseline_times), 5, \"Should collect baseline measurements\")\nE   AssertionError: 0 not greater than 5 : Should collect baseline measurements\n_______________ TestACC13SLOEndpoints.test_discover_slo_services _______________\ntests/test_acc13_slo.py:45: in test_discover_slo_services\n    self.assertEqual(result.returncode, 0, \"Should be able to get services from edge2\")\nE   AssertionError: 1 != 0 : Should be able to get services from edge2\n________________ TestACC13SLOEndpoints.test_load_test_moves_p95 ________________\ntests/test_acc13_slo.py:171: in test_load_test_moves_p95\n    self.assertGreater(load_p95, baseline_p95 * 0.8,\nE   AssertionError: 0 not greater than 0.0 : P95 should increase under load (or stay similar if system handles load well)\n____________ TestACC13SLOEndpoints.test_slo_endpoints_are_reachable ____________\ntests/test_acc13_slo.py:86: in test_slo_endpoints_are_reachable\n    self.test_discover_slo_services()\ntests/test_acc13_slo.py:45: in test_discover_slo_services\n    self.assertEqual(result.returncode, 0, \"Should be able to get services from edge2\")\nE   AssertionError: 1 != 0 : Should be able to get services from edge2\n______________ TestACC13Performance.test_concurrent_load_handling ______________\ntests/test_acc13_slo.py:292: in test_concurrent_load_handling\n    \"p95\": self._calculate_percentile(response_times, 95),\n           ^^^^^^^^^^^^^^^^^^^^^^^^^^^^^^^^^^^^^^^^^^^^^^\ntests/test_acc13_slo.py:306: in _calculate_percentile\n    return statistics.quantiles(sorted(data), n=100)[percentile-1]\n           ^^^^^^^^^^^^^^^^^^^^^^^^^^^^^^^^^^^^^^^^^\n.pyenv/versions/3.11.9/lib/python3.11/statistics.py:794: in quantiles\n    raise StatisticsError('must have at least two data points')\nE   statistics.StatisticsError: must have at least two data points\n--------------------------------- JSON report ----------------------------------\nreport saved to: artifacts/edge1/acc-13_test_results.json\n=========================== short test summary info ============================\nFAILED tests/test_acc13_slo.py::TestACC13SLOEndpoints::test_baseline_response_time_measurement\nFAILED tests/test_acc13_slo.py::TestACC13SLOEndpoints::test_discover_slo_services\nFAILED tests/test_acc13_slo.py::TestACC13SLOEndpoints::test_load_test_moves_p95\nFAILED tests/test_acc13_slo.py::TestACC13SLOEndpoints::test_slo_endpoints_are_reachable\nFAILED tests/test_acc13_slo.py::TestACC13Performance::test_concurrent_load_handling\n========================= 5 failed, 3 passed in 4.34s ==========================\n",
      "test_errors": "",
      "return_code": 1
    },
    {
      "phase": "ACC-19",
      "status": "FAIL",
      "duration_seconds": 3.54,
      "test_output": "============================= test session starts ==============================\nplatform linux -- Python 3.11.9, pytest-8.4.2, pluggy-1.6.0 -- /home/ubuntu/.pyenv/versions/3.11.9/bin/python3\ncachedir: .pytest_cache\nmetadata: {'Python': '3.11.9', 'Platform': 'Linux-5.15.0-100-generic-x86_64-with-glibc2.35', 'Packages': {'pytest': '8.4.2', 'pluggy': '1.6.0'}, 'Plugins': {'json-report': '1.5.0', 'metadata': '3.1.1', 'timeout': '2.4.0'}}\nrootdir: /home/ubuntu\nplugins: json-report-1.5.0, metadata-3.1.1, timeout-2.4.0\ncollecting ... collected 9 items\n\ntests/test_acc19_pr_verification.py::TestACC19O2IMSProvisioningRequest::test_discover_pr_crd_resources FAILED [ 11%]\ntests/test_acc19_pr_verification.py::TestACC19O2IMSProvisioningRequest::test_generate_acc19_artifacts FAILED [ 22%]\ntests/test_acc19_pr_verification.py::TestACC19O2IMSProvisioningRequest::test_pr_crd_definition_exists FAILED [ 33%]\ntests/test_acc19_pr_verification.py::TestACC19O2IMSProvisioningRequest::test_pr_resource_lifecycle_state FAILED [ 44%]\ntests/test_acc19_pr_verification.py::TestACC19O2IMSProvisioningRequest::test_pr_resource_validation_schema FAILED [ 55%]\ntests/test_acc19_pr_verification.py::TestACC19O2IMSProvisioningRequest::test_pr_resources_have_ready_status FAILED [ 66%]\ntests/test_acc19_pr_verification.py::TestACC19O2IMSProvisioningRequest::test_pr_services_are_reachable FAILED [ 77%]\ntests/test_acc19_pr_verification.py::TestACC19Integration::test_end_to_end_pr_verification_workflow FAILED [ 88%]\ntests/test_acc19_pr_verification.py::TestACC19Integration::test_verification_artifacts_completeness PASSED [100%]\n\n=================================== FAILURES ===================================\n_______ TestACC19O2IMSProvisioningRequest.test_discover_pr_crd_resources _______\ntests/test_acc19_pr_verification.py:78: in test_discover_pr_crd_resources\n    self.assertGreater(len(discovered_crds), 0,\nE   AssertionError: 0 not greater than 0 : Should discover at least one ProvisioningRequest CRD resource\n_______ TestACC19O2IMSProvisioningRequest.test_generate_acc19_artifacts ________\ntests/test_acc19_pr_verification.py:303: in test_generate_acc19_artifacts\n    self.test_discover_pr_crd_resources()\ntests/test_acc19_pr_verification.py:78: in test_discover_pr_crd_resources\n    self.assertGreater(len(discovered_crds), 0,\nE   AssertionError: 0 not greater than 0 : Should discover at least one ProvisioningRequest CRD resource\n_______ TestACC19O2IMSProvisioningRequest.test_pr_crd_definition_exists ________\ntests/test_acc19_pr_verification.py:95: in test_pr_crd_definition_exists\n    self.assertEqual(result.returncode, 0, \"Should be able to query CRDs\")\nE   AssertionError: 1 != 0 : Should be able to query CRDs\n______ TestACC19O2IMSProvisioningRequest.test_pr_resource_lifecycle_state ______\ntests/test_acc19_pr_verification.py:262: in test_pr_resource_lifecycle_state\n    self.test_discover_pr_crd_resources()\ntests/test_acc19_pr_verification.py:78: in test_discover_pr_crd_resources\n    self.assertGreater(len(discovered_crds), 0,\nE   AssertionError: 0 not greater than 0 : Should discover at least one ProvisioningRequest CRD resource\n_____ TestACC19O2IMSProvisioningRequest.test_pr_resource_validation_schema _____\ntests/test_acc19_pr_verification.py:204: in test_pr_resource_validation_schema\n    self.test_discover_pr_crd_resources()\ntests/test_acc19_pr_verification.py:78: in test_discover_pr_crd_resources\n    self.assertGreater(len(discovered_crds), 0,\nE   AssertionError: 0 not greater than 0 : Should discover at least one ProvisioningRequest CRD resource\n____ TestACC19O2IMSProvisioningRequest.test_pr_resources_have_ready_status _____\ntests/test_acc19_pr_verification.py:113: in test_pr_resources_have_ready_status\n    self.test_discover_pr_crd_resources()\ntests/test_acc19_pr_verification.py:78: in test_discover_pr_crd_resources\n    self.assertGreater(len(discovered_crds), 0,\nE   AssertionError: 0 not greater than 0 : Should discover at least one ProvisioningRequest CRD resource\n_______ TestACC19O2IMSProvisioningRequest.test_pr_services_are_reachable _______\ntests/test_acc19_pr_verification.py:163: in test_pr_services_are_reachable\n    self.assertEqual(result.returncode, 0, \"Should be able to get services\")\nE   AssertionError: 1 != 0 : Should be able to get services\n________ TestACC19Integration.test_end_to_end_pr_verification_workflow _________\ntests/test_acc19_pr_verification.py:387: in test_end_to_end_pr_verification_workflow\n    self.assertEqual(result.failures, [], \"No verification steps should fail\")\nE   AssertionError: Lists differ: [(<test_acc19_pr_verification.TestACC19O2I[3338 chars]\\n')] != []\nE   \nE   First list contains 7 additional elements.\nE   First extra element 0:\nE   (<test_acc19_pr_verification.TestACC19O2IMSProvisioningRequest testMethod=test_discover_pr_crd_resources>, 'Traceback (most recent call last):\\n  File \"/home/ubuntu/tests/test_acc19_pr_verification.py\", line 78, in test_discover_pr_crd_resources\\n    self.assertGreater(len(discovered_crds), 0,\\nAssertionError: 0 not greater than 0 : Should discover at least one ProvisioningRequest CRD resource\\n')\nE   \nE   Diff is 3761 characters long. Set self.maxDiff to None to see it. : No verification steps should fail\n----------------------------- Captured stderr call -----------------------------\n======================================================================\nFAIL: test_discover_pr_crd_resources (test_acc19_pr_verification.TestACC19O2IMSProvisioningRequest.test_discover_pr_crd_resources)\nTest: Should discover ProvisioningRequest CRD resources across all namespaces\n----------------------------------------------------------------------\nTraceback (most recent call last):\n  File \"/home/ubuntu/tests/test_acc19_pr_verification.py\", line 78, in test_discover_pr_crd_resources\n    self.assertGreater(len(discovered_crds), 0,\nAssertionError: 0 not greater than 0 : Should discover at least one ProvisioningRequest CRD resource\n\n======================================================================\nFAIL: test_generate_acc19_artifacts (test_acc19_pr_verification.TestACC19O2IMSProvisioningRequest.test_generate_acc19_artifacts)\nTest: Should generate comprehensive acc19_ready.json artifact\n----------------------------------------------------------------------\nTraceback (most recent call last):\n  File \"/home/ubuntu/tests/test_acc19_pr_verification.py\", line 303, in test_generate_acc19_artifacts\n    self.test_discover_pr_crd_resources()\n  File \"/home/ubuntu/tests/test_acc19_pr_verification.py\", line 78, in test_discover_pr_crd_resources\n    self.assertGreater(len(discovered_crds), 0,\nAssertionError: 0 not greater than 0 : Should discover at least one ProvisioningRequest CRD resource\n\n======================================================================\nFAIL: test_pr_crd_definition_exists (test_acc19_pr_verification.TestACC19O2IMSProvisioningRequest.test_pr_crd_definition_exists)\nTest: ProvisioningRequest CRD definition should exist in cluster\n----------------------------------------------------------------------\nTraceback (most recent call last):\n  File \"/home/ubuntu/tests/test_acc19_pr_verification.py\", line 95, in test_pr_crd_definition_exists\n    self.assertEqual(result.returncode, 0, \"Should be able to query CRDs\")\nAssertionError: 1 != 0 : Should be able to query CRDs\n\n======================================================================\nFAIL: test_pr_resource_lifecycle_state (test_acc19_pr_verification.TestACC19O2IMSProvisioningRequest.test_pr_resource_lifecycle_state)\nTest: PR resources should show proper lifecycle state progression\n----------------------------------------------------------------------\nTraceback (most recent call last):\n  File \"/home/ubuntu/tests/test_acc19_pr_verification.py\", line 262, in test_pr_resource_lifecycle_state\n    self.test_discover_pr_crd_resources()\n  File \"/home/ubuntu/tests/test_acc19_pr_verification.py\", line 78, in test_discover_pr_crd_resources\n    self.assertGreater(len(discovered_crds), 0,\nAssertionError: 0 not greater than 0 : Should discover at least one ProvisioningRequest CRD resource\n\n======================================================================\nFAIL: test_pr_resource_validation_schema (test_acc19_pr_verification.TestACC19O2IMSProvisioningRequest.test_pr_resource_validation_schema)\nTest: PR resources should conform to expected schema structure\n----------------------------------------------------------------------\nTraceback (most recent call last):\n  File \"/home/ubuntu/tests/test_acc19_pr_verification.py\", line 204, in test_pr_resource_validation_schema\n    self.test_discover_pr_crd_resources()\n  File \"/home/ubuntu/tests/test_acc19_pr_verification.py\", line 78, in test_discover_pr_crd_resources\n    self.assertGreater(len(discovered_crds), 0,\nAssertionError: 0 not greater than 0 : Should discover at least one ProvisioningRequest CRD resource\n\n======================================================================\nFAIL: test_pr_resources_have_ready_status (test_acc19_pr_verification.TestACC19O2IMSProvisioningRequest.test_pr_resources_have_ready_status)\nTest: ProvisioningRequest resources should be in READY state\n----------------------------------------------------------------------\nTraceback (most recent call last):\n  File \"/home/ubuntu/tests/test_acc19_pr_verification.py\", line 113, in test_pr_resources_have_ready_status\n    self.test_discover_pr_crd_resources()\n  File \"/home/ubuntu/tests/test_acc19_pr_verification.py\", line 78, in test_discover_pr_crd_resources\n    self.assertGreater(len(discovered_crds), 0,\nAssertionError: 0 not greater than 0 : Should discover at least one ProvisioningRequest CRD resource\n\n======================================================================\nFAIL: test_pr_services_are_reachable (test_acc19_pr_verification.TestACC19O2IMSProvisioningRequest.test_pr_services_are_reachable)\nTest: Services associated with PRs should be reachable\n----------------------------------------------------------------------\nTraceback (most recent call last):\n  File \"/home/ubuntu/tests/test_acc19_pr_verification.py\", line 163, in test_pr_services_are_reachable\n    self.assertEqual(result.returncode, 0, \"Should be able to get services\")\nAssertionError: 1 != 0 : Should be able to get services\n\n----------------------------------------------------------------------\nRan 7 tests in 1.495s\n\nFAILED (failures=7)\n--------------------------------- JSON report ----------------------------------\nreport saved to: artifacts/edge1/acc-19_test_results.json\n=========================== short test summary info ============================\nFAILED tests/test_acc19_pr_verification.py::TestACC19O2IMSProvisioningRequest::test_discover_pr_crd_resources\nFAILED tests/test_acc19_pr_verification.py::TestACC19O2IMSProvisioningRequest::test_generate_acc19_artifacts\nFAILED tests/test_acc19_pr_verification.py::TestACC19O2IMSProvisioningRequest::test_pr_crd_definition_exists\nFAILED tests/test_acc19_pr_verification.py::TestACC19O2IMSProvisioningRequest::test_pr_resource_lifecycle_state\nFAILED tests/test_acc19_pr_verification.py::TestACC19O2IMSProvisioningRequest::test_pr_resource_validation_schema\nFAILED tests/test_acc19_pr_verification.py::TestACC19O2IMSProvisioningRequest::test_pr_resources_have_ready_status\nFAILED tests/test_acc19_pr_verification.py::TestACC19O2IMSProvisioningRequest::test_pr_services_are_reachable\nFAILED tests/test_acc19_pr_verification.py::TestACC19Integration::test_end_to_end_pr_verification_workflow\n========================= 8 failed, 1 passed in 3.22s ==========================\n",
      "test_errors": "",
      "return_code": 1
    }
  ],
  "overall_status": "FAIL",
  "summary_statistics": {
    "total_phases": 3,
    "passed_phases": 0,
    "failed_phases": 3,
    "error_phases": 0
  },
  "tdd_compliance": {
    "test_first_approach": true,
    "red_green_refactor_cycle": true,
    "automated_verification": true,
    "continuous_integration_ready": true,
    "artifact_generation": true
  }
}